<?xml version="1.0" ?>
<!-- =================================================================================== -->
<!-- |    This document was autogenerated by xacro from /home/work/ros/mycatkin_ws/src/mycobot_test/mycobot_description/urdf/mycobot_robot.urdf.xacro | -->
<!-- |    EDITING THIS FILE BY HAND IS NOT RECOMMENDED                                 | -->
<!-- =================================================================================== -->
<!-- Open_Manipulator Chain -->
<robot name="mycobot">
    <!-- World -->
    <gazebo reference="world" />
    <!-- Link1 -->
    <RefLink ref="link1" />
    <!-- Link2 -->
    <RefLink ref="link2" />
    <!-- Link3 -->
    <RefLink ref="link3" />
    <!-- Link4 -->
    <RefLink ref="link4" />
    <!-- Link5 -->
    <RefLink ref="link5" />
    <!-- Link6 -->
    <RefLink ref="link6" />
    
    <!-- ros_control plugin -->
    <gazebo>
        <plugin filename="libgazebo_ros_control.so" name="gazebo_ros_control">
            <controlPeriod>0.001</controlPeriod>
            <robotSimType>gazebo_ros_control/DefaultRobotHWSim</robotSimType>
            <legacyModeNS>true</legacyModeNS>
        </plugin>
    </gazebo>
    <transmission name="tran1">
        <type>transmission_interface/SimpleTransmission</type>
        <joint name="joint1">
            <hardwareInterface>hardware_interface/EffortJointInterface</hardwareInterface>
        </joint>
        <actuator name="motor1">
            <hardwareInterface>hardware_interface/EffortJointInterface</hardwareInterface>
            <mechanicalReduction>1</mechanicalReduction>
        </actuator>
    </transmission>
    <transmission name="tran2">
        <type>transmission_interface/SimpleTransmission</type>
        <joint name="joint2">
            <hardwareInterface>hardware_interface/EffortJointInterface</hardwareInterface>
        </joint>
        <actuator name="motor2">
            <hardwareInterface>hardware_interface/EffortJointInterface</hardwareInterface>
            <mechanicalReduction>1</mechanicalReduction>
        </actuator>
    </transmission>
    <transmission name="tran3">
        <type>transmission_interface/SimpleTransmission</type>
        <joint name="joint3">
            <hardwareInterface>hardware_interface/EffortJointInterface</hardwareInterface>
        </joint>
        <actuator name="motor3">
            <hardwareInterface>hardware_interface/EffortJointInterface</hardwareInterface>
            <mechanicalReduction>1</mechanicalReduction>
        </actuator>
    </transmission>
    <transmission name="tran4">
        <type>transmission_interface/SimpleTransmission</type>
        <joint name="joint4">
            <hardwareInterface>hardware_interface/EffortJointInterface</hardwareInterface>
        </joint>
        <actuator name="motor4">
            <hardwareInterface>hardware_interface/EffortJointInterface</hardwareInterface>
            <mechanicalReduction>1</mechanicalReduction>
        </actuator>
    </transmission>
    <transmission name="tran5">
        <type>transmission_interface/SimpleTransmission</type>
        <joint name="joint5">
            <hardwareInterface>hardware_interface/EffortJointInterface</hardwareInterface>
        </joint>
        <actuator name="motor5">
            <hardwareInterface>hardware_interface/EffortJointInterface</hardwareInterface>
            <mechanicalReduction>1</mechanicalReduction>
        </actuator>
    </transmission>
    <transmission name="tran6">
        <type>transmission_interface/SimpleTransmission</type>
        <joint name="joint6">
            <hardwareInterface>hardware_interface/EffortJointInterface</hardwareInterface>
        </joint>
        <actuator name="motor6">
            <hardwareInterface>hardware_interface/EffortJointInterface</hardwareInterface>
            <mechanicalReduction>1</mechanicalReduction>
        </actuator>
    </transmission>
    <link name="link1">
        <visual>
            <geometry>
                <!--- 0.0 0 -0.04  1.5708 3.14159-->
                <mesh filename="package://mycobot_description/urdf/components/joint1.dae" />
            </geometry>
            <origin rpy="0 0 -1.5708" xyz="0.0 0 0" />
        </visual>
        <collision>
            <geometry>
                <!--- 0.0 0 -0.04  1.5708 3.14159-->
                <mesh filename="package://mycobot_description/urdf/components/joint1.dae" />
            </geometry>
            <origin rpy="0 0 -1.5708" xyz="0.0 0 0" />
        </collision>
        
<inertial>
            <origin xyz="0 0 0" />
            <mass value="1.0e-03" />
            <inertia ixx="1.0e-03" ixy="0.0" ixz="0.0" iyy="1.0e-03" iyz="0.0" izz="1.0e-03" />
        </inertial>

    </link>
    <joint name="joint1" type="revolute">
        <axis xyz="0 0 1" />
        <limit effort="1000.0" lower="-3.14" upper="3.14159" velocity="0" />
        <parent link="link1" />
        <child link="link2" />
        <origin rpy="0 0 0" xyz="0 0 0.13156" />
    </joint>
    <link name="link2">
        <visual>
            <geometry>
                <mesh filename="package://mycobot_description/urdf/components/joint2.dae" />
            </geometry>
            <origin rpy="0 0 -1.5708" xyz="0.0 0 -0.06096" />
        </visual>
        <collision>
            <geometry>
                <mesh filename="package://mycobot_description/urdf/components/joint2.dae" />
            </geometry>
            <origin rpy="0 0 -1.5708" xyz="0.0 0 -0.06096" />
        </collision>
        
<inertial>
            <origin xyz="0 0 0" />
            <mass value="1.0e-03" />
            <inertia ixx="1.0e-03" ixy="0.0" ixz="0.0" iyy="1.0e-03" iyz="0.0" izz="1.0e-03" />
        </inertial>

    </link>
    <joint name="joint2" type="revolute">
        <axis xyz="0 0 1" />
        <limit effort="1000.0" lower="-3.14" upper="3.14159" velocity="0" />
        <parent link="link2" />
        <child link="link3" />
        <origin rpy="0 1.5708 -1.5708" xyz="0 0  0" />
    </joint>
    <link name="link3">
        <visual>
            <geometry>
                <mesh filename="package://mycobot_description/urdf/components/joint3.dae" />
            </geometry>
            <origin rpy="0 -1.5708 0" xyz="0.0 0 0.03256" />
        </visual>
        <collision>
            <geometry>
                <mesh filename="package://mycobot_description/urdf/components/joint3.dae" />
            </geometry>
            <origin rpy="0 -1.5708 0" xyz="0.0 0 0.03256" />
        </collision>
        
<inertial>
            <origin xyz="0 0 0" />
            <mass value="1.0e-03" />
            <inertia ixx="1.0e-03" ixy="0.0" ixz="0.0" iyy="1.0e-03" iyz="0.0" izz="1.0e-03" />
        </inertial>

    </link>
    <joint name="joint3" type="revolute">
        <axis xyz="0 0 1" />
        <limit effort="1000.0" lower="-3.14" upper="3.14159" velocity="0" />
        <parent link="link3" />
        <child link="link4" />
        <origin rpy="0 0 0" xyz="-0.1104 0 0" />
    </joint>
    <link name="link4">
        <visual>
            <geometry>
                <!--- 0.0 0 -0.04 -->
                <mesh filename="package://mycobot_description/urdf/components/joint4.dae" />
            </geometry>
            <origin rpy="0 -1.5708 0" xyz="0.0 0 0.03056" />
        </visual>
        <collision>
            <geometry>
                <!--- 0.0 0 -0.04 -->
                <mesh filename="package://mycobot_description/urdf/components/joint4.dae" />
            </geometry>
            <origin rpy="0 -1.5708 0" xyz="0.0 0 0.03056" />
        </collision>
        
<inertial>
            <origin xyz="0 0 0" />
            <mass value="1.0e-03" />
            <inertia ixx="1.0e-03" ixy="0.0" ixz="0.0" iyy="1.0e-03" iyz="0.0" izz="1.0e-03" />
        </inertial>

    </link>
    <joint name="joint4" type="revolute">
        <axis xyz="0 0 1" />
        <limit effort="1000.0" lower="-3.14" upper="3.14159" velocity="0" />
        <parent link="link4" />
        <child link="link5" />
        <origin rpy="0 0 -1.5708" xyz="-0.096 0 0.06462" />
    </joint>
    <link name="link5">
        <visual>
            <geometry>
                <!--- 0.0 0 -0.04 -->
                <mesh filename="package://mycobot_description/urdf/components/joint5.dae" />
            </geometry>
            <origin rpy="-1.5708 0 0" xyz="0.0 0 -0.03356" />
        </visual>
        <collision>
            <geometry>
                <!--- 0.0 0 -0.04 -->
                <mesh filename="package://mycobot_description/urdf/components/joint5.dae" />
            </geometry>
            <origin rpy="-1.5708 0 0" xyz="0.0 0 -0.03356" />
        </collision>
        
<inertial>
            <origin xyz="0 0 0" />
            <mass value="1.0e-03" />
            <inertia ixx="1.0e-03" ixy="0.0" ixz="0.0" iyy="1.0e-03" iyz="0.0" izz="1.0e-03" />
        </inertial>

    </link>
    <joint name="joint5" type="revolute">
        <axis xyz="0 0 1" />
        <limit effort="1000.0" lower="-3.14" upper="3.14159" velocity="0" />
        <parent link="link5" />
        <child link="link6" />
        <origin rpy="1.5708 -1.5708 0" xyz="0 -0.07318 0" />
    </joint>
    <link name="link6">
        <visual>
            <geometry>
                <!--- 0.0 0 -0.04 -->
                <mesh filename="package://mycobot_description/urdf/components/joint6.dae" />
            </geometry>
            <origin rpy="0 0 0" xyz="0 0.00 -0.038" />
        </visual>
        <collision>
            <geometry>
                <!--- 0.0 0 -0.04 -->
                <mesh filename="package://mycobot_description/urdf/components/joint6.dae" />
            </geometry>
            <origin rpy="0 0 0" xyz="0 0.00 -0.038" />
        </collision>
        
<inertial>
            <origin xyz="0 0 0" />
            <mass value="1.0e-03" />
            <inertia ixx="1.0e-03" ixy="0.0" ixz="0.0" iyy="1.0e-03" iyz="0.0" izz="1.0e-03" />
        </inertial>

    </link>
    <joint name="joint6" type="revolute">
        <axis xyz="0 0 1" />
        <limit effort="1000.0" lower="-3.14" upper="3.14159" velocity="0" />
        <parent link="link6" />
        <child link="link7" />
        <origin rpy="-1.5708 0 0" xyz="0 0.0456 0" />
    </joint>
    <link name="link7">
        <visual>
            <geometry>
                <!--- 0.0 0 -0.04 -->
                <mesh filename="package://mycobot_description/urdf/components/joint7.dae" />
            </geometry>
            <origin rpy="0 0 0" xyz="0.0 0 -0.012" />
        </visual>
        <collision>
            <geometry>
                <!--- 0.0 0 -0.04 -->
                <mesh filename="package://mycobot_description/urdf/components/joint7.dae" />
            </geometry>
            <origin rpy="0 0 0" xyz="0.0 0 -0.012" />
        </collision>
        
<inertial>
            <mass value="0.1" />
            <inertia ixx="0.03" iyy="0.03" izz="0.03" ixy="0.0" ixz="0.0" iyz="0.0" />
        </inertial>

    </link>
    <!-- World -->
    <link name="world" />
    <!-- World fixed joint-->
    <joint name="world_fixed" type="fixed">
        <origin rpy="0 0 0" xyz="0 0 0" />
        <parent link="world" />
        <child link="link1" />
    </joint>
    <transmission name="trans_joint1">
        <type>transmission_interface/SimpleTransmission</type>
        <joint name="joint1">
            <hardwareInterface>hardware_interface/EffortJointInterface</hardwareInterface>
        </joint>
        <actuator name="joint1_motor">
            <hardwareInterface>hardware_interface/EffortJointInterface</hardwareInterface>
            <mechanicalReduction>1</mechanicalReduction>
        </actuator>
    </transmission>
    <transmission name="trans_joint2">
        <type>transmission_interface/SimpleTransmission</type>
        <joint name="joint2">
            <hardwareInterface>hardware_interface/EffortJointInterface</hardwareInterface>
        </joint>
        <actuator name="joint2_motor">
            <hardwareInterface>hardware_interface/EffortJointInterface</hardwareInterface>
            <mechanicalReduction>1</mechanicalReduction>
        </actuator>
    </transmission>
    <transmission name="trans_joint3">
        <type>transmission_interface/SimpleTransmission</type>
        <joint name="joint3">
            <hardwareInterface>hardware_interface/EffortJointInterface</hardwareInterface>
        </joint>
        <actuator name="joint3_motor">
            <hardwareInterface>hardware_interface/EffortJointInterface</hardwareInterface>
            <mechanicalReduction>1</mechanicalReduction>
        </actuator>
    </transmission>
    <transmission name="trans_joint4">
        <type>transmission_interface/SimpleTransmission</type>
        <joint name="joint4">
            <hardwareInterface>hardware_interface/EffortJointInterface</hardwareInterface>
        </joint>
        <actuator name="joint4_motor">
            <hardwareInterface>hardware_interface/EffortJointInterface</hardwareInterface>
            <mechanicalReduction>1</mechanicalReduction>
        </actuator>
    </transmission>
    <transmission name="trans_joint5">
        <type>transmission_interface/SimpleTransmission</type>
        <joint name="joint5">
            <hardwareInterface>hardware_interface/EffortJointInterface</hardwareInterface>
        </joint>
        <actuator name="joint5_motor">
            <hardwareInterface>hardware_interface/EffortJointInterface</hardwareInterface>
            <mechanicalReduction>1</mechanicalReduction>
        </actuator>
    </transmission>
    <transmission name="trans_joint6">
        <type>transmission_interface/SimpleTransmission</type>
        <joint name="joint6">
            <hardwareInterface>hardware_interface/EffortJointInterface</hardwareInterface>
        </joint>
        <actuator name="joint6_motor">
            <hardwareInterface>hardware_interface/EffortJointInterface</hardwareInterface>
            <mechanicalReduction>1</mechanicalReduction>
        </actuator>
    </transmission>
    <gazebo>
        <plugin name="gazebo_ros_control" filename="libgazebo_ros_control.so">
            <robotNamespace>/</robotNamespace>
        </plugin>
    </gazebo>
</robot>

<transmission name="tran1">
        <type>transmission_interface/SimpleTransmission</type>
        <joint name="joint1">
            <hardwareInterface>hardware_interface/EffortJointInterface</hardwareInterface>
        </joint>
        <actuator name="motor1">
            <hardwareInterface>hardware_interface/EffortJointInterface</hardwareInterface>
            <mechanicalReduction>1</mechanicalReduction>
        </actuator>
    </transmission>
    <transmission name="tran2">
        <type>transmission_interface/SimpleTransmission</type>
        <joint name="joint2">
            <hardwareInterface>hardware_interface/EffortJointInterface</hardwareInterface>
        </joint>
        <actuator name="motor2">
            <hardwareInterface>hardware_interface/EffortJointInterface</hardwareInterface>
            <mechanicalReduction>1</mechanicalReduction>
        </actuator>
    </transmission>
    <transmission name="tran3">
        <type>transmission_interface/SimpleTransmission</type>
        <joint name="joint3">
            <hardwareInterface>hardware_interface/EffortJointInterface</hardwareInterface>
        </joint>
        <actuator name="motor3">
            <hardwareInterface>hardware_interface/EffortJointInterface</hardwareInterface>
            <mechanicalReduction>1</mechanicalReduction>
        </actuator>
    </transmission>
    <transmission name="tran4">
        <type>transmission_interface/SimpleTransmission</type>
        <joint name="joint4">
            <hardwareInterface>hardware_interface/EffortJointInterface</hardwareInterface>
        </joint>
        <actuator name="motor4">
            <hardwareInterface>hardware_interface/EffortJointInterface</hardwareInterface>
            <mechanicalReduction>1</mechanicalReduction>
        </actuator>
    </transmission>
    <transmission name="tran5">
        <type>transmission_interface/SimpleTransmission</type>
        <joint name="joint5">
            <hardwareInterface>hardware_interface/EffortJointInterface</hardwareInterface>
        </joint>
        <actuator name="motor5">
            <hardwareInterface>hardware_interface/EffortJointInterface</hardwareInterface>
            <mechanicalReduction>1</mechanicalReduction>
        </actuator>
    </transmission>
    <transmission name="tran6">
        <type>transmission_interface/SimpleTransmission</type>
        <joint name="joint6">
            <hardwareInterface>hardware_interface/EffortJointInterface</hardwareInterface>
        </joint>
        <actuator name="motor6">
            <hardwareInterface>hardware_interface/EffortJointInterface</hardwareInterface>
            <mechanicalReduction>1</mechanicalReduction>
        </actuator>
    </transmission>
    <link name="link1">
        <visual>
            <geometry>
                <!--- 0.0 0 -0.04  1.5708 3.14159-->
                <mesh filename="package://mycobot_description/urdf/components/joint1.dae" />
            </geometry>
            <origin rpy="0 0 -1.5708" xyz="0.0 0 0" />
        </visual>
        <collision>
            <geometry>
                <!--- 0.0 0 -0.04  1.5708 3.14159-->
                <mesh filename="package://mycobot_description/urdf/components/joint1.dae" />
            </geometry>
            <origin rpy="0 0 -1.5708" xyz="0.0 0 0" />
        </collision>
        <inertial>
            <origin xyz="0 0 0" />
            <mass value="1.0e-03" />
            <inertia ixx="1.0e-03" ixy="0.0" ixz="0.0" iyy="1.0e-03" iyz="0.0" izz="1.0e-03" />
        </inertial>
    </link>
    <joint name="joint1" type="revolute">
        <axis xyz="0 0 1" />
        <limit effort="1000.0" lower="-3.14" upper="3.14159" velocity="0" />
        <parent link="link1" />
        <child link="link2" />
        <origin rpy="0 0 0" xyz="0 0 0.13156" />
    </joint>
    <link name="link2">
        <visual>
            <geometry>
                <mesh filename="package://mycobot_description/urdf/components/joint2.dae" />
            </geometry>
            <origin rpy="0 0 -1.5708" xyz="0.0 0 -0.06096" />
        </visual>
        <collision>
            <geometry>
                <mesh filename="package://mycobot_description/urdf/components/joint2.dae" />
            </geometry>
            <origin rpy="0 0 -1.5708" xyz="0.0 0 -0.06096" />
        </collision>
        <inertial>
            <origin xyz="0 0 0" />
            <mass value="1.0e-03" />
            <inertia ixx="1.0e-03" ixy="0.0" ixz="0.0" iyy="1.0e-03" iyz="0.0" izz="1.0e-03" />
        </inertial>
    </link>
    <joint name="joint2" type="revolute">
        <axis xyz="0 0 1" />
        <limit effort="1000.0" lower="-3.14" upper="3.14159" velocity="0" />
        <parent link="link2" />
        <child link="link3" />
        <origin rpy="0 1.5708 -1.5708" xyz="0 0  0" />
    </joint>
    <link name="link3">
        <visual>
            <geometry>
                <mesh filename="package://mycobot_description/urdf/components/joint3.dae" />
            </geometry>
            <origin rpy="0 -1.5708 0" xyz="0.0 0 0.03256" />
        </visual>
        <collision>
            <geometry>
                <mesh filename="package://mycobot_description/urdf/components/joint3.dae" />
            </geometry>
            <origin rpy="0 -1.5708 0" xyz="0.0 0 0.03256" />
        </collision>
        <inertial>
            <origin xyz="0 0 0" />
            <mass value="1.0e-03" />
            <inertia ixx="1.0e-03" ixy="0.0" ixz="0.0" iyy="1.0e-03" iyz="0.0" izz="1.0e-03" />
        </inertial>
    </link>
    <joint name="joint3" type="revolute">
        <axis xyz="0 0 1" />
        <limit effort="1000.0" lower="-3.14" upper="3.14159" velocity="0" />
        <parent link="link3" />
        <child link="link4" />
        <origin rpy="0 0 0" xyz="-0.1104 0 0" />
    </joint>
    <link name="link4">
        <visual>
            <geometry>
                <!--- 0.0 0 -0.04 -->
                <mesh filename="package://mycobot_description/urdf/components/joint4.dae" />
            </geometry>
            <origin rpy="0 -1.5708 0" xyz="0.0 0 0.03056" />
        </visual>
        <collision>
            <geometry>
                <!--- 0.0 0 -0.04 -->
                <mesh filename="package://mycobot_description/urdf/components/joint4.dae" />
            </geometry>
            <origin rpy="0 -1.5708 0" xyz="0.0 0 0.03056" />
        </collision>
        <inertial>
            <origin xyz="0 0 0" />
            <mass value="1.0e-03" />
            <inertia ixx="1.0e-03" ixy="0.0" ixz="0.0" iyy="1.0e-03" iyz="0.0" izz="1.0e-03" />
        </inertial>
    </link>
    <joint name="joint4" type="revolute">
        <axis xyz="0 0 1" />
        <limit effort="1000.0" lower="-3.14" upper="3.14159" velocity="0" />
        <parent link="link4" />
        <child link="link5" />
        <origin rpy="0 0 -1.5708" xyz="-0.096 0 0.06462" />
    </joint>
    <link name="link5">
        <visual>
            <geometry>
                <!--- 0.0 0 -0.04 -->
                <mesh filename="package://mycobot_description/urdf/components/joint5.dae" />
            </geometry>
            <origin rpy="-1.5708 0 0" xyz="0.0 0 -0.03356" />
        </visual>
        <collision>
            <geometry>
                <!--- 0.0 0 -0.04 -->
                <mesh filename="package://mycobot_description/urdf/components/joint5.dae" />
            </geometry>
            <origin rpy="-1.5708 0 0" xyz="0.0 0 -0.03356" />
        </collision>
        <inertial>
            <origin xyz="0 0 0" />
            <mass value="1.0e-03" />
            <inertia ixx="1.0e-03" ixy="0.0" ixz="0.0" iyy="1.0e-03" iyz="0.0" izz="1.0e-03" />
        </inertial>
    </link>
    <joint name="joint5" type="revolute">
        <axis xyz="0 0 1" />
        <limit effort="1000.0" lower="-3.14" upper="3.14159" velocity="0" />
        <parent link="link5" />
        <child link="link6" />
        <origin rpy="1.5708 -1.5708 0" xyz="0 -0.07318 0" />
    </joint>
    <link name="link6">
        <visual>
            <geometry>
                <!--- 0.0 0 -0.04 -->
                <mesh filename="package://mycobot_description/urdf/components/joint6.dae" />
            </geometry>
            <origin rpy="0 0 0" xyz="0 0.00 -0.038" />
        </visual>
        <collision>
            <geometry>
                <!--- 0.0 0 -0.04 -->
                <mesh filename="package://mycobot_description/urdf/components/joint6.dae" />
            </geometry>
            <origin rpy="0 0 0" xyz="0 0.00 -0.038" />
        </collision>
        <inertial>
            <origin xyz="0 0 0" />
            <mass value="1.0e-03" />
            <inertia ixx="1.0e-03" ixy="0.0" ixz="0.0" iyy="1.0e-03" iyz="0.0" izz="1.0e-03" />
        </inertial>
    </link>
    <joint name="joint6" type="revolute">
        <axis xyz="0 0 1" />
        <limit effort="1000.0" lower="-3.14" upper="3.14159" velocity="0" />
        <parent link="link6" />
        <child link="link7" />
        <origin rpy="-1.5708 0 0" xyz="0 0.0456 0" />
    </joint>
    <link name="link7">
        <visual>
            <geometry>
                <!--- 0.0 0 -0.04 -->
                <mesh filename="package://mycobot_description/urdf/components/joint7.dae" />
            </geometry>
            <origin rpy="0 0 0" xyz="0.0 0 -0.012" />
        </visual>
        <collision>
            <geometry>
                <!--- 0.0 0 -0.04 -->
                <mesh filename="package://mycobot_description/urdf/components/joint7.dae" />
            </geometry>
            <origin rpy="0 0 0" xyz="0.0 0 -0.012" />
        </collision>
        <inertial>
            <mass value="0.1" />
            <inertia ixx="0.03" iyy="0.03" izz="0.03" ixy="0.0" ixz="0.0" iyz="0.0" />
        </inertial>
    </link>
    <!-- World -->
    <link name="world" />
    <!-- World fixed joint-->
    <joint name="world_fixed" type="fixed">
        <origin rpy="0 0 0" xyz="0 0 0" />
        <parent link="world" />
        <child link="link1" />
    </joint>
    <transmission name="trans_joint1">
        <type>transmission_interface/SimpleTransmission</type>
        <joint name="joint1">
            <hardwareInterface>hardware_interface/EffortJointInterface</hardwareInterface>
        </joint>
        <actuator name="joint1_motor">
            <hardwareInterface>hardware_interface/EffortJointInterface</hardwareInterface>
            <mechanicalReduction>1</mechanicalReduction>
        </actuator>
    </transmission>
    <transmission name="trans_joint2">
        <type>transmission_interface/SimpleTransmission</type>
        <joint name="joint2">
            <hardwareInterface>hardware_interface/EffortJointInterface</hardwareInterface>
        </joint>
        <actuator name="joint2_motor">
            <hardwareInterface>hardware_interface/EffortJointInterface</hardwareInterface>
            <mechanicalReduction>1</mechanicalReduction>
        </actuator>
    </transmission>
    <transmission name="trans_joint3">
        <type>transmission_interface/SimpleTransmission</type>
        <joint name="joint3">
            <hardwareInterface>hardware_interface/EffortJointInterface</hardwareInterface>
        </joint>
        <actuator name="joint3_motor">
            <hardwareInterface>hardware_interface/EffortJointInterface</hardwareInterface>
            <mechanicalReduction>1</mechanicalReduction>
        </actuator>
    </transmission>
    <transmission name="trans_joint4">
        <type>transmission_interface/SimpleTransmission</type>
        <joint name="joint4">
            <hardwareInterface>hardware_interface/EffortJointInterface</hardwareInterface>
        </joint>
        <actuator name="joint4_motor">
            <hardwareInterface>hardware_interface/EffortJointInterface</hardwareInterface>
            <mechanicalReduction>1</mechanicalReduction>
        </actuator>
    </transmission>
    <transmission name="trans_joint5">
        <type>transmission_interface/SimpleTransmission</type>
        <joint name="joint5">
            <hardwareInterface>hardware_interface/EffortJointInterface</hardwareInterface>
        </joint>
        <actuator name="joint5_motor">
            <hardwareInterface>hardware_interface/EffortJointInterface</hardwareInterface>
            <mechanicalReduction>1</mechanicalReduction>
        </actuator>
    </transmission>
    <transmission name="trans_joint6">
        <type>transmission_interface/SimpleTransmission</type>
        <joint name="joint6">
            <hardwareInterface>hardware_interface/EffortJointInterface</hardwareInterface>
        </joint>
        <actuator name="joint6_motor">
            <hardwareInterface>hardware_interface/EffortJointInterface</hardwareInterface>
            <mechanicalReduction>1</mechanicalReduction>
        </actuator>
    </transmission>
    <gazebo>
        <plugin name="gazebo_ros_control" filename="libgazebo_ros_control.so">
            <robotNamespace>/</robotNamespace>
        </plugin>
    </gazebo>
</robot>